{
 "cells": [
  {
   "cell_type": "code",
   "execution_count": 2,
   "metadata": {
    "ExecuteTime": {
     "end_time": "2019-03-27T09:47:06.451281Z",
     "start_time": "2019-03-27T09:47:06.329623Z"
    }
   },
   "outputs": [],
   "source": [
    "import numpy as np"
   ]
  },
  {
   "cell_type": "code",
   "execution_count": null,
   "metadata": {
    "ExecuteTime": {
     "start_time": "2019-03-27T09:55:39.817Z"
    }
   },
   "outputs": [
    {
     "ename": "ModuleNotFoundError",
     "evalue": "No module named 'numpy.core._multiarray_umath'",
     "output_type": "error",
     "traceback": [
      "\u001b[1;31m---------------------------------------------------------------------------\u001b[0m",
      "\u001b[1;31mModuleNotFoundError\u001b[0m                       Traceback (most recent call last)",
      "\u001b[1;31mModuleNotFoundError\u001b[0m: No module named 'numpy.core._multiarray_umath'"
     ]
    },
    {
     "ename": "SystemError",
     "evalue": "<class '_frozen_importlib._ModuleLockManager'> returned a result with an error set",
     "output_type": "error",
     "traceback": [
      "\u001b[1;31m---------------------------------------------------------------------------\u001b[0m",
      "\u001b[1;31mImportError\u001b[0m                               Traceback (most recent call last)",
      "\u001b[1;31mImportError\u001b[0m: numpy.core.multiarray failed to import",
      "\nThe above exception was the direct cause of the following exception:\n",
      "\u001b[1;31mSystemError\u001b[0m                               Traceback (most recent call last)",
      "\u001b[1;32m~\\AppData\\Local\\Continuum\\anaconda3\\lib\\importlib\\_bootstrap.py\u001b[0m in \u001b[0;36m_find_and_load\u001b[1;34m(name, import_)\u001b[0m\n",
      "\u001b[1;31mSystemError\u001b[0m: <class '_frozen_importlib._ModuleLockManager'> returned a result with an error set"
     ]
    },
    {
     "ename": "ImportError",
     "evalue": "numpy.core._multiarray_umath failed to import",
     "output_type": "error",
     "traceback": [
      "\u001b[1;31m---------------------------------------------------------------------------\u001b[0m",
      "\u001b[1;31mImportError\u001b[0m                               Traceback (most recent call last)",
      "\u001b[1;31mImportError\u001b[0m: numpy.core._multiarray_umath failed to import"
     ]
    },
    {
     "ename": "ImportError",
     "evalue": "numpy.core.umath failed to import",
     "output_type": "error",
     "traceback": [
      "\u001b[1;31m---------------------------------------------------------------------------\u001b[0m",
      "\u001b[1;31mImportError\u001b[0m                               Traceback (most recent call last)",
      "\u001b[1;31mImportError\u001b[0m: numpy.core.umath failed to import"
     ]
    }
   ],
   "source": [
    "import tensorflow as tf"
   ]
  },
  {
   "cell_type": "code",
   "execution_count": 3,
   "metadata": {
    "ExecuteTime": {
     "end_time": "2019-03-27T09:47:09.771337Z",
     "start_time": "2019-03-27T09:47:09.764316Z"
    }
   },
   "outputs": [
    {
     "data": {
      "text/plain": [
       "'1.15.4'"
      ]
     },
     "execution_count": 3,
     "metadata": {},
     "output_type": "execute_result"
    }
   ],
   "source": [
    "np.__version__"
   ]
  },
  {
   "cell_type": "code",
   "execution_count": 6,
   "metadata": {
    "ExecuteTime": {
     "end_time": "2019-03-27T09:48:27.981900Z",
     "start_time": "2019-03-27T09:48:27.978893Z"
    }
   },
   "outputs": [
    {
     "data": {
      "text/plain": [
       "'C:\\\\Users\\\\taacodo4\\\\AppData\\\\Local\\\\Continuum\\\\anaconda3\\\\lib\\\\site-packages\\\\numpy\\\\__init__.py'"
      ]
     },
     "execution_count": 6,
     "metadata": {},
     "output_type": "execute_result"
    }
   ],
   "source": [
    "np.__file__"
   ]
  },
  {
   "cell_type": "code",
   "execution_count": null,
   "metadata": {
    "ExecuteTime": {
     "start_time": "2019-03-27T09:44:19.333Z"
    }
   },
   "outputs": [
    {
     "name": "stderr",
     "output_type": "stream",
     "text": [
      "Using TensorFlow backend.\n"
     ]
    },
    {
     "ename": "ModuleNotFoundError",
     "evalue": "No module named 'numpy.core._multiarray_umath'",
     "output_type": "error",
     "traceback": [
      "\u001b[1;31m---------------------------------------------------------------------------\u001b[0m",
      "\u001b[1;31mModuleNotFoundError\u001b[0m                       Traceback (most recent call last)",
      "\u001b[1;31mModuleNotFoundError\u001b[0m: No module named 'numpy.core._multiarray_umath'"
     ]
    },
    {
     "ename": "SystemError",
     "evalue": "<class '_frozen_importlib._ModuleLockManager'> returned a result with an error set",
     "output_type": "error",
     "traceback": [
      "\u001b[1;31m---------------------------------------------------------------------------\u001b[0m",
      "\u001b[1;31mImportError\u001b[0m                               Traceback (most recent call last)",
      "\u001b[1;31mImportError\u001b[0m: numpy.core.multiarray failed to import",
      "\nThe above exception was the direct cause of the following exception:\n",
      "\u001b[1;31mSystemError\u001b[0m                               Traceback (most recent call last)",
      "\u001b[1;32m~\\AppData\\Local\\Continuum\\anaconda3\\lib\\importlib\\_bootstrap.py\u001b[0m in \u001b[0;36m_find_and_load\u001b[1;34m(name, import_)\u001b[0m\n",
      "\u001b[1;31mSystemError\u001b[0m: <class '_frozen_importlib._ModuleLockManager'> returned a result with an error set"
     ]
    },
    {
     "ename": "ImportError",
     "evalue": "numpy.core._multiarray_umath failed to import",
     "output_type": "error",
     "traceback": [
      "\u001b[1;31m---------------------------------------------------------------------------\u001b[0m",
      "\u001b[1;31mImportError\u001b[0m                               Traceback (most recent call last)",
      "\u001b[1;31mImportError\u001b[0m: numpy.core._multiarray_umath failed to import"
     ]
    },
    {
     "ename": "ImportError",
     "evalue": "numpy.core.umath failed to import",
     "output_type": "error",
     "traceback": [
      "\u001b[1;31m---------------------------------------------------------------------------\u001b[0m",
      "\u001b[1;31mImportError\u001b[0m                               Traceback (most recent call last)",
      "\u001b[1;31mImportError\u001b[0m: numpy.core.umath failed to import"
     ]
    }
   ],
   "source": [
    "from keras.models import Sequential"
   ]
  }
 ],
 "metadata": {
  "kernelspec": {
   "display_name": "Python 3",
   "language": "python",
   "name": "python3"
  },
  "language_info": {
   "codemirror_mode": {
    "name": "ipython",
    "version": 3
   },
   "file_extension": ".py",
   "mimetype": "text/x-python",
   "name": "python",
   "nbconvert_exporter": "python",
   "pygments_lexer": "ipython3",
   "version": "3.7.1"
  },
  "toc": {
   "base_numbering": 1,
   "nav_menu": {},
   "number_sections": true,
   "sideBar": true,
   "skip_h1_title": false,
   "title_cell": "Table of Contents",
   "title_sidebar": "Contents",
   "toc_cell": false,
   "toc_position": {},
   "toc_section_display": true,
   "toc_window_display": false
  }
 },
 "nbformat": 4,
 "nbformat_minor": 2
}
